Workbook

Sheet Listas
A1: Sí/No | B1: Estado civil | C1: Tipo sociedad | D1: Tipo vínculo | E1: Origen acciones | F1: Estado documento | G1: Nivel riesgo | H1: 01. Constitución y existencia de las empresas | I1: 02. Libros, actas y órganos societarios | J1: 03. Acciones, cuotas y participaciones | K1: 04. Restricciones, negociación y acuerdos entre accionistas | L1: 05. Información financiera, contable y tributaria | M1: 06. Valoración de empresas y acciones | N1: 07. Bienes inmuebles y patrimonio material | O1: 08. Marcas, propiedad intelectual e intangibles | P1: 09. Protocolo familiar y gobierno de la familia | Q1: 10. Políticas familiares y empresariales | R1: 11. Estado civil, matrimonio y unión marital | S1: 12. Sucesiones y testamentos | T1: 13. Donaciones, usufructos y estructuras fiduciarias | U1: 15. Administración, representación y poderes | V1: 16. Familiares que trabajan en la empresa | W1: 17. Contratos entre familiares, accionistas y empresas | X1: 18. Riesgos, litigios y contingencias | Y1: 19. Conceptos, auditorías y asesorías profesionales | Z1: 20. Implementación y control documental | AA1: Estructura recomendada para las carpetas
A2: Sí | B2: Soltero(a) | C2: S.A.S. | D2: Fundador(a) | E2: Constitución | F2: Existe y está actualizado | G2: Bajo | H2: Documento de constitución de la sociedad | I2: Libro de actas de asamblea general de accionistas | J2: Títulos de acciones | K2: Acuerdo de accionistas | L2: Estados financieros del último año | M2: Avalúo o valoración de la empresa | N2: Certificado de tradición y libertad de inmueble | O2: Certificado de registro de marca | P2: Protocolo de familia | Q2: Política de empleo de familiares | R2: Registro civil de nacimiento | S2: Testamento abierto | T2: Contrato de donación | U2: Poder general | V2: Contrato laboral de familiar | W2: Contrato entre la sociedad y un familiar | X2: Relación de procesos judiciales | Y2: Concepto jurídico societario | Z2: Plan integral de implementación | AA2: 01_Constitucion_y_existencia
A3: No | B3: Casado(a) | C3: S.A. | D3: Hijo(a) | E3: Compra | F3: Existe, requiere revisión | G3: Medio | H3: Acta de constitución | I3: Libro de actas de junta directiva | J3: Certificados de acciones | K3: Pacto de socios | L3: Estados financieros históricos | M3: Valoración patrimonial contable | N3: Escritura pública de adquisición de inmueble | O3: Solicitud de registro de marca | P3: Borrador del protocolo de familia | Q3: Política de ingreso de familiares a la empresa | R3: Registro civil de matrimonio | S3: Testamento cerrado | T3: Escritura pública de donación | U3: Poder especial | V3: Contrato de prestación de servicios de familiar | W3: Contrato de arrendamiento entre familiar y empresa | X3: Relación de procesos administrativos | Y3: Concepto jurídico de familia | Z3: Cronograma de implementación | AA3: 02_Libros_actas_y_organos
A4: No sabe | B4: Unión libre | C4: Ltda. | D4: Nieto(a) | E4: Donación | F4: No existe | G4: Alto | H4: Estatutos sociales vigentes | I4: Libro de registro de accionistas | J4: Documento de suscripción de acciones | K4: Autorización para negociación de acciones | L4: Estado de situación financiera | M4: Valoración patrimonial ajustada | N4: Contrato de compraventa de inmueble | O4: Documento de propiedad de marca | P4: Acta de aprobación del protocolo de familia | Q4: Política salarial para familiares | R4: Registro civil de defunción | S4: Copia auténtica del testamento | T4: Documento de donación de acciones | U4: Autorización para representación de accionista | V4: Descripción del cargo de familiar | W4: Contrato de préstamo entre familiar y empresa | X4: Relación de procesos tributarios | Y4: Concepto jurídico sucesoral | Z4: Matriz de implementación jurídica | AA4: 03_Acciones_y_participaciones
A5: No aplica | B5: Divorciado(a) | C5: Empresa unipersonal | D5: Cónyuge/compañero(a) | E5: Herencia | F5: En preparación | G5: Crítico | H5: Reforma estatutaria inicial | I5: Actas de asamblea general de accionistas | J5: Reglamento de emisión y colocación de acciones | K5: Oferta de venta de acciones | L5: Estado de resultados | M5: Valoración de acciones o participaciones | N5: Promesa de compraventa de inmueble | O5: Contrato de licencia de marca | P5: Documento de adhesión al protocolo de familia | Q5: Política de evaluación de familiares | R5: Documento de identidad | S5: Escritura pública de testamento | T5: Documento de donación de inmueble | U5: Documento de instrucciones en caso de incapacidad | V5: Manual de funciones de familiar | W5: Contrato de compraventa entre familiar y empresa | X5: Relación de procesos laborales | Y5: Concepto tributario | Z5: Matriz de responsables | AA5: 04_Acuerdos_y_restricciones
B6: Viudo(a) | C6: Persona natural | D6: Hermano(a) | E6: Capitalización | F6: No sabe | H6: Última reforma estatutaria | I6: Actas de reuniones extraordinarias de accionistas | J6: Documento de capitalización | K6: Ejercicio del derecho de preferencia | L6: Estado de flujo de efectivo | M6: Valor intrínseco por acción | N6: Documento de adjudicación de inmueble | O6: Contrato de cesión de marca | P6: Documento de actualización del protocolo de familia | Q6: Política de ascenso de familiares | R6: Capitulaciones matrimoniales | S6: Modificación de testamento | T6: Documento de donación con condiciones | U6: Documento de designación de suplente | V6: Hoja de vida del familiar | W6: Contrato de prestación de servicios entre familiar y empresa | X6: Relación de contingencias | Y6: Concepto contable | Z6: Matriz de documentos pendientes | AA6: 05_Financiero_contable_tributario
B7: Separado(a) | C7: Fundación/ESAL | D7: Otro familiar | E7: Cesión | F7: No aplica | H7: Histórico de reformas estatutarias | I7: Actas de junta directiva | J7: Documento de adquisición de acciones | K7: Renuncia al derecho de preferencia | L7: Estado de cambios en el patrimonio | M7: Valor comercial de acciones | N7: Avalúo comercial de inmueble | O7: Documento de propiedad intelectual | P7: Acta de reunión familiar | Q7: Política de retiro de familiares | R7: Capitulaciones maritales | S7: Revocatoria de testamento | T7: Documento de donación con reserva de usufructo | U7: Acta de nombramiento de representante legal | V7: Soportes académicos del familiar | W7: Contrato de mandato entre familiar y empresa | X7: Demanda judicial | Y7: Concepto financiero | Z7: Lista de chequeo documental | AA7: 06_Valoraciones
B8: Por confirmar | C8: Otra | D8: No familiar | E8: Otro | H8: Certificado de existencia y representación legal | I8: Reglamento de la asamblea de accionistas | J8: Contrato de compraventa de acciones | K8: Opción de compra de acciones | L8: Notas a los estados financieros | M8: Informe financiero de valoración | N8: Avalúo catastral de inmueble | O8: Registro de derechos de autor | P8: Acta de Asamblea de Familia | Q8: Política de dividendos | R8: Escritura pública de capitulaciones | S8: Inventario sucesoral | T8: Documento de constitución de usufructo | U8: Acta de nombramiento de representante legal suplente | V8: Evaluación de desempeño de familiar | W8: Contrato de usufructo entre familiar y empresa | X8: Contestación de demanda | Y8: Concepto de valoración | Z8: Acta de entrega de documentos | AA8: 07_Inmuebles_y_activos
E9: Adjud. Liquid. comunidad | H9: Registro Único Tributario – RUT | I9: Reglamento de junta directiva | J9: Promesa de compraventa de acciones | K9: Opción de venta de acciones | L9: Certificación de estados financieros | M9: Valoración por flujo de caja descontado | N9: Recibo del impuesto predial | O9: Contrato de licencia de software | P9: Acta del Consejo de Familia | Q9: Política de reinversión de utilidades | R9: Modificación de capitulaciones | S9: Trabajo de partición y adjudicación | T9: Documento de reserva de usufructo | U9: Acta de nombramiento de junta directiva | V9: Plan de formación del familiar | W9: Contrato de cesión entre familiar y empresa | X9: Sentencia judicial | Y9: Informe de debida diligencia | Z9: Inventario general de documentos | AA9: 08_Marcas_e_intangibles
H10: Matrícula mercantil | I10: Acta de nombramiento de representante legal | J10: Contrato de cesión de acciones | K10: Derecho de primera oferta | L10: Dictamen del revisor fiscal | M10: Valoración por múltiplos | N10: Certificado catastral | O10: Contrato de cesión de derechos de autor | P10: Reglamento del Consejo de Familia | Q10: Política de préstamos a familiares | R10: Inventario anexo a capitulaciones | S10: Escritura de sucesión | T10: Documento de terminación de usufructo | U10: Acta de aceptación del cargo | V10: Plan de carrera del familiar | W10: Documento de cuenta por cobrar a accionista | X10: Acuerdo de conciliación | Y10: Informe de auditoría jurídica | Z10: Índice del archivo familiar | AA10: 09_Protocolo_y_gobierno_familiar
H11: Documento de renovación de matrícula mercantil | I11: Acta de nombramiento de junta directiva | J11: Contrato de donación de acciones | K11: Derecho de primera negociación | L11: Declaración de renta de la sociedad | M11: Valoración de activos | N11: Contrato de arrendamiento de inmueble | O11: Documento de propiedad de dominio web | P11: Reglamento de la Asamblea de Familia | Q11: Política de ayudas familiares | R11: Declaración de unión marital de hecho | S11: Sentencia de sucesión | T11: Documento de nuda propiedad | U11: Carta de renuncia de administrador | V11: Documento de remuneración del familiar | W11: Documento de cuenta por pagar a accionista | X11: Laudo arbitral | Y11: Informe de auditoría societaria | Z11: Índice del archivo societario | AA11: 10_Politicas_familiares
H12: Objeto social vigente | I12: Acta de aceptación del cargo | J12: Documento de aceptación de donación | K12: Acuerdo de permanencia accionaria | L12: Declaraciones tributarias relevantes | M12: Valoración de intangibles | N12: Documento de propiedad de vehículos | O12: Inventario de activos intangibles | P12: Árbol genealógico familiar | Q12: Política de uso de bienes de la empresa | R12: Escritura de declaración de unión marital de hecho | S12: Acta de adjudicación de herencia | T12: Fideicomiso civil | U12: Declaración de conflicto de interés | V12: Acuerdo de confidencialidad del familiar | W12: Autorización de operación con parte relacionada | X12: Contrato de transacción | Y12: Informe de auditoría patrimonial | Z12: Constancia de inexistencia del documento | AA12: 11_Estado_civil_y_capitulaciones
H13: Certificación de actividad económica | I13: Carta de renuncia de administrador | J13: Documento de transferencia de acciones | K13: Acuerdo de voto | L13: Información exógena | M13: Valoración de marca | N13: Tarjeta de propiedad de vehículos | O13: Valoración de marca | P13: Mapa de la familia empresaria | Q13: Política de vehículos empresariales | R13: Sentencia de declaración de unión marital de hecho | S13: Documento de aceptación de herencia | T13: Contrato de fiducia mercantil | U13: Certificado de antecedentes de administradores | V13: Acuerdo de no competencia del familiar | W13: Acta de aprobación de operación con parte relacionada | X13: Documento de embargo | Y13: Informe de auditoría contable | Z13: Documento pendiente de localizar | AA13: 12_Sucesiones_y_testamentos
H14: Documento de transformación societaria | I14: Certificación de composición accionaria | J14: Documento de adjudicación de acciones | K14: Acuerdo de sindicación de acciones | L14: Conciliación fiscal | M14: Valoración de cartera | N14: Inventario de maquinaria y equipos | O14: Valoración de propiedad intelectual | P14: Mapa societario | Q14: Política de gastos personales | R14: Documento de constitución de sociedad patrimonial | S14: Documento de repudio de herencia | T14: Patrimonio autónomo | U14: Informe de gestión del representante legal | V14: Declaración de conflicto de interés del familiar | W14: Informe de operaciones con vinculados | X14: Documento de secuestro | Y14: Informe de auditoría tributaria | Z14: Documento pendiente de actualización | AA14: 13_Donaciones_usufructos_y_fiducias
H15: Documento de fusión | I15: Certificación expedida por representante legal | J15: Registro de transferencia en el libro de accionistas | K15: Acuerdo de confidencialidad entre accionistas | L15: Informe de cartera y obligaciones | M15: Informe de perito independiente | N15: Inventario de muebles y enseres | O15: Acuerdo de confidencialidad | P15: Mapa de composición accionaria | Q15: Política de operaciones con partes relacionadas | R15: Escritura de disolución de sociedad patrimonial | S15: Certificado de derechos sucesorales | T15: Encargo fiduciario | U15: Reglamento de funciones del representante legal | V15: Autorización para operaciones con familiares | W15: Estudio de condiciones de mercado | X15: Documento de medida cautelar | Y15: Informe de auditoría laboral | Z15: Documento no aplicable | AA15: 14_Seguros
H16: Documento de escisión | I16: Certificación expedida por revisor fiscal | J16: Soporte de pago o aporte de acciones | K16: Acuerdo de no competencia | L16: Relación de activos y pasivos | M16: Concepto de valoración | N16: Documento de propiedad de otros activos | O16: Acuerdo de protección de secretos empresariales | P16: Mapa patrimonial | Q16: Política de conflictos de interés | R16: Escritura de liquidación de sociedad patrimonial | S16: Cesión de derechos herenciales | T16: Reglamento fiduciario | U16: Manual de gobierno corporativo | V16: Documento de retiro del familiar | W16: Declaración de conflicto de interés | X16: Informe de riesgos legales | Y16: Informe de auditoría de gobierno corporativo | Z16: Solicitud de copia de documento | AA16: 15_Administracion_y_poderes
H17: Documento de disolución de la sociedad | J17: Documento de readquisición de acciones | K17: Restricción estatutaria a la negociación de acciones | L17: Relación de contingencias judiciales | M17: Metodología de valoración de acciones | N17: Relación de inmuebles familiares | P17: Matriz de riesgos familiares | Q17: Política de confidencialidad | R17: Sentencia de disolución y liquidación de sociedad patrimonial | S17: Contrato de compraventa de derechos herenciales | T17: Certificado de derechos fiduciarios | U17: Documento de delegación de funciones | V17: Liquidación laboral del familiar | X17: Informe de riesgos societarios | Y17: Informe de revisión de estatutos | Z17: Copia simple del documento | AA17: 16_Familiares_trabajadores
H18: Documento de liquidación de la sociedad | J18: Documento de cancelación de acciones | K18: Procedimiento de ingreso de nuevos accionistas | L18: Relación de garantías otorgadas | M18: Política de valoración y compra de acciones | N18: Relación de inmuebles societarios | P18: Matriz de riesgos societarios | Q18: Política de no competencia | R18: Escritura de disolución de sociedad conyugal | S18: Acuerdo entre herederos | T18: Contrato de administración fiduciaria | U18: Documento de límites de autorización | V18: Política de empleo de familiares | X18: Informe de riesgos familiares | Y18: Informe de revisión del libro de accionistas | Z18: Copia auténtica del documento | AA18: 17_Contratos_con_familiares
J19: Documento de conversión de acciones | K19: Procedimiento de retiro de accionistas | L19: Relación de créditos y obligaciones financieras | N19: Relación de bienes en copropiedad | P19: Matriz de riesgos sucesorales | Q19: Política de solución de conflictos | R19: Escritura de liquidación de sociedad conyugal | S19: Documento de designación de albacea | T19: Documento de instrucciones fiduciarias | V19: Política salarial para familiares | X19: Informe de riesgos sucesorales | Y19: Informe de planeación sucesoral | Z19: Versión preliminar | AA19: 18_Riesgos_y_litigios
A20: Hoja auxiliar para listas desplegables. No requiere diligenciamiento. | J20: Documento de usufructo de acciones | K20: Procedimiento de compra de acciones por divorcio | L20: Relación de cuentas por cobrar | N20: Documento de hipoteca | P20: Matriz de implementación jurídica | Q20: Política de ingreso de nuevos accionistas | R20: Sentencia de divorcio | S20: Documento de aceptación del cargo de albacea | T20: Informe de la fiduciaria | X20: Matriz de riesgos familiares | Y20: Informe de planeación patrimonial | Z20: Versión aprobada | AA20: 19_Conceptos_y_auditorias
J21: Documento de nuda propiedad de acciones | K21: Procedimiento de compra de acciones por fallecimiento | L21: Relación de cuentas por pagar | N21: Documento de levantamiento de hipoteca | P21: Código de ética familiar y empresarial | Q21: Política de retiro de accionistas | R21: Sentencia de separación de bienes | S21: Documento de designación de tutor | X21: Matriz de riesgos societarios | Z21: Versión firmada | AA21: 20_Implementacion_y_control
J22: Documento de prenda sobre acciones | K22: Procedimiento de compra de acciones por incapacidad | L22: Documento de cuenta por cobrar a accionista | N22: Documento de embargo | P22: Manual de gobierno corporativo | Q22: Política de sucesión gerencial | R22: Acta de conciliación sobre bienes | S22: Documento de designación de curador | X22: Matriz de riesgos sucesorales | Z22: Versión registrada
J23: Documento de liberación de prenda sobre acciones | L23: Documento de cuenta por pagar a accionista | N23: Documento de levantamiento de embargo | P23: Manual de administración del patrimonio familiar | Q23: Política de sucesión accionaria | R23: Acuerdo patrimonial entre cónyuges | S23: Plan de sucesión accionaria | X23: Plan de tratamiento de riesgos | Z23: Otro documento
L24: Informe de operaciones con vinculados | P24: Plan de formación de nuevas generaciones | Q24: Política de valoración y compra de acciones | R24: Acuerdo patrimonial entre compañeros permanentes | S24: Plan de sucesión patrimonial
L25: Informe de partes relacionadas | P25: Plan de comunicación familiar | Q25: Política de venta de activos estratégicos | R25: Inventario de bienes propios | S25: Plan de sucesión gerencial
L26: Presupuesto anual | Q26: Política de endeudamiento | R26: Inventario de bienes sociales | S26: Inventario de herederos
L27: Flujo de caja proyectado | Q27: Política de garantías otorgadas por la empresa | R27: Inventario de bienes personales | S27: Registro civil de los herederos
R28: Certificación de estado civil

Sheet 00_Instrucciones
A1: DIAGNÓSTICO Y BASES DEL PROTOCOLO DE LA FAMILIA ABUITA
A4: Objetivo de la plantilla
A5: Reunir en un solo archivo la información familiar, societaria y patrimonial necesaria para preparar el Protocolo Familiar, la reforma de estatutos, los acuerdos de accionistas, las capitulaciones o liquidaciones patrimoniales y la planeación sucesoral.
A9: Orden recomendado de diligenciamiento
A10: Paso | B10: Hoja | C10: Qué diligenciar | D10: Resultado
A11: 1 | B11: Familia | C11: Registre fundadores, hijos, cónyuges y demás familiares relevantes. | D11: 01_Familia
A12: 2 | B12: Empresas | C12: Incluya todas las sociedades y negocios familiares. | D12: 02_Empresas
A13: 3 | B13: Accionistas | C13: Relacione quién posee acciones, cómo y cuándo las adquirió. | D13: 03_Accionistas
A14: 4 | B14: Patrimonio | C14: Registre bienes relevantes sin incluir información bancaria sensible. | D14: 04_Patrimonio
A15: 5 | B15: Documentos | C15: Identifique estatutos, acuerdos, capitulaciones, testamentos y seguros. | D15: 05_Documentos
A16: 6 | B16: Riesgos | C16: Evalúe matrimonio, divorcio, fallecimiento, incapacidad y conflictos. | D16: 06_Riesgos
A17: 7 | B17: Decisiones | C17: Consigne la voluntad familiar y los documentos donde deberá ejecutarse. | D17: 07_Decisiones
A18: 8 | B18: Resumen | C18: Revise pendientes, alertas y avance general. | D18: 08_Resumen
A20: Reglas para diligenciar
A21: • No registrar números de cédula, cuentas bancarias ni claves. • Utilizar porcentajes aproximados cuando todavía no se tenga el certificado o libro de accionistas. • Marcar “No sabe” cuando la información deba verificarse; no dejar el dato como cierto por suposición. • Una fila corresponde a una persona, sociedad, participación, bien, documento, riesgo o decisión. • La información será revisada jurídicamente antes de firmar cualquier reforma o instrumento.
A27: CÓMO INTERPRETAR CADA FILA
A28: Hoja | B28: Qué representa una fila | C28: Regla práctica
A29: 01_Familia | B29: Una fila representa una persona. | C29: No repitas a la misma persona salvo que necesites corregirla.
A30: 02_Empresas | B30: Una fila representa una empresa. | C30: Incluye también sociedades patrimoniales o empresas inactivas con bienes.
A31: 03_Accionistas | B31: Una fila representa un accionista dentro de una empresa. | C31: Repite la empresa por cada accionista; los porcentajes de esa empresa deben sumar 100%.
A32: 04_Patrimonio | B32: Una fila representa un bien o activo. | C32: No incluyas cuentas, claves ni datos bancarios sensibles.
A33: 05_Documentos | B33: Una fila representa un documento. | C33: Marca “No sabe” cuando sea necesario verificar.
A34: 06_Riesgos | B34: Una fila representa un evento que podría afectar a la familia o empresa. | C34: No se necesita una conclusión jurídica definitiva en esta etapa.
A35: 07_Decisiones | B35: Una fila representa una regla que la familia debe acordar. | C35: Primero se define la voluntad y después se traduce a documentos jurídicos.

Sheet 01_Familia
A1: 01. MAPA DE LA FAMILIA EMPRESARIA
A3: OBJETIVO: identificar a las personas que integran la familia empresaria y su relación con las empresas. UNIDAD DE REGISTRO: una fila por cada persona. Primera generación: fundadores; segunda: hijos; tercera: nietos. Los cónyuges se identifican como familia política.
A4: Código | B4: Nombre completo | C4: Tipo de vínculo | D4: Generación | E4: Edad | F4: Estado civil | G4: Año matrimonio/convivencia | H4: Tiene capitulaciones | I4: Sociedad conyugal/patrimonial liquidada | J4: Número de hijos | K4: Trabaja en empresa familiar | L4: Empresa donde trabaja | M4: Cargo | N4: Es accionista | O4: Participa en decisiones | P4: Observaciones
A5: =IF(B5="","","FAM-"&TEXT(ROW()-4,"000")) -> FAM-001 | B5: Nassif Abuita Nassar | C5: Fundador(a) | D5: Primera Generacion | E5: 65 | F5: Divorciado(a) | H5: No | I5: Sí | J5: 2 | K5: Sí | L5: Soluciones Comerciales y Cosntructuvas S.A.S | M5: Representante Legal | N5: si | O5: Sí
A6: =IF(B6="","","FAM-"&TEXT(ROW()-4,"000")) -> FAM-002 | B6: Gloria Maria Correa Rivera | C6: Fundador(a) | D6: Primera Generacion | E6: 68 | F6: Divorciado(a) | H6: No | I6: Sí | J6: 2 | K6: Sí | L6: Soluciones Comerciales y Cosntructuvas S.A.S | M6: Representante Legal Suplente | N6: si | O6: Sí
A7: =IF(B7="","","FAM-"&TEXT(ROW()-4,"000")) -> FAM-003 | B7: Said Latif Abuita Correa | C7: Hijo(a) | D7: Segunda Generacion | E7: 35 | F7: Unión libre | H7: No | J7: 0 | K7: Sí | L7: Soluciones Comerciales y Cosntructuvas S.A.S | M7: Gerente Comercial | N7: si | O7: Sí
A8: =IF(B8="","","FAM-"&TEXT(ROW()-4,"000")) -> FAM-004 | B8: Karam Nassif Abuita Correa | C8: Hijo(a) | D8: Segunda Generacion | E8: 31 | F8: Soltero(a) | H8: No | J8: 0 | K8: No | L8: Traditun S.A.S | M8: Representante Legal | N8: si | O8: Sí
A9: =IF(B9="","","FAM-"&TEXT(ROW()-4,"000"))
A10: =IF(B10="","","FAM-"&TEXT(ROW()-4,"000"))
A11: =IF(B11="","","FAM-"&TEXT(ROW()-4,"000"))
A12: =IF(B12="","","FAM-"&TEXT(ROW()-4,"000"))
A13: =IF(B13="","","FAM-"&TEXT(ROW()-4,"000"))
A14: =IF(B14="","","FAM-"&TEXT(ROW()-4,"000"))
A15: =IF(B15="","","FAM-"&TEXT(ROW()-4,"000"))
A16: =IF(B16="","","FAM-"&TEXT(ROW()-4,"000"))
A17: =IF(B17="","","FAM-"&TEXT(ROW()-4,"000"))
A18: =IF(B18="","","FAM-"&TEXT(ROW()-4,"000"))
A19: =IF(B19="","","FAM-"&TEXT(ROW()-4,"000"))
A20: =IF(B20="","","FAM-"&TEXT(ROW()-4,"000"))
... A54: =IF(B54="","","FAM-"&TEXT(ROW()-4,"000"))

Sheet 02_Empresas
A1: 02. INVENTARIO DE EMPRESAS Y NEGOCIOS
A3: OBJETIVO: conocer todas las sociedades y negocios familiares, su función, administración y estado documental. UNIDAD DE REGISTRO: una fila por cada empresa o negocio.
A4: Código | B4: Razón social | C4: Nombre comercial | D4: Tipo de sociedad | E4: Año creación | F4: Actividad principal | G4: Empresa operativa/patrimonial | H4: Representante legal | I4: Tiene junta directiva | J4: Tiene revisor fiscal | K4: Tiene inmuebles propios | L4: Tiene empleados | M4: Deudas o créditos importantes | N4: Estatutos actualizados | O4: Acuerdo de accionistas | P4: Libro de accionistas actualizado | Q4: Nivel de riesgo | R4: Observaciones
A5: =IF(B5="","","EMP-"&TEXT(ROW()-4,"000")) -> EMP-001 | B5: Soluciones Comerciales y Constructivas | C5: Sk&c | D5: S.A.S. | E5: 41425 | F5: ciiu 6820 -Actividades inmobiliarias realizadas a cambio de una retribución o por contrata. Incluye los servicios de bienes raíces prestados por terceros. | G5: Operativa | H5: Nassif Abuita Nassar | I5: No | J5: No | K5: Sí | L5: Sí | M5: Prestamos Bancarios | N5: No | O5: No | P5: No | Q5: Medio | R5: Definir las siglas que cambia a SK&C-SuCasa Inmobiliaria. No contamos con Junta directiva: Los Organos de direccion es la Asamblea General
A6: =IF(B6="","","EMP-"&TEXT(ROW()-4,"000")) -> EMP-002 | B6: Diseños y Soluciones Creativas | C6: DSC | D6: S.A.S. | E6: 38511 | F6: ciiu 6820 -Actividades inmobiliarias realizadas a cambio de una retribución o por contrata. Incluye los servicios de bienes raíces prestados por terceros. | G6: Patrimonial | H6: Nassif Abuita Nassar | I6: Si | J6: No | K6: Sí | L6: No | M6: No Posee | N6: No | O6: No | P6: No | Q6: Bajo | R6: Empresa Patrimonial ,No tiene operaciones comerciales , solo maneja 2 contratos de terceros que no se han podido trasladar a Soluciones Comerciales y Constructivas y el ingreso por el alquiler del inmueble propio
A7: =IF(B7="","","EMP-"&TEXT(ROW()-4,"000"))
A8: =IF(B8="","","EMP-"&TEXT(ROW()-4,"000"))
A9: =IF(B9="","","EMP-"&TEXT(ROW()-4,"000"))
A10: =IF(B10="","","EMP-"&TEXT(ROW()-4,"000"))
A11: =IF(B11="","","EMP-"&TEXT(ROW()-4,"000"))
A12: =IF(B12="","","EMP-"&TEXT(ROW()-4,"000"))
A13: =IF(B13="","","EMP-"&TEXT(ROW()-4,"000"))
A14: =IF(B14="","","EMP-"&TEXT(ROW()-4,"000"))
A15: =IF(B15="","","EMP-"&TEXT(ROW()-4,"000"))
A16: =IF(B16="","","EMP-"&TEXT(ROW()-4,"000"))
A17: =IF(B17="","","EMP-"&TEXT(ROW()-4,"000"))
A18: =IF(B18="","","EMP-"&TEXT(ROW()-4,"000"))
... A34: =IF(B34="","","EMP-"&TEXT(ROW()-4,"000"))

Sheet 03_Accionistas
A1: 03. COMPOSICIÓN ACCIONARIA Y ORIGEN DE LAS PARTICIPACIONES
A3: OBJETIVO: establecer quién es propietario de cada empresa, desde cuándo y cómo adquirió su participación. REGLA PRINCIPAL: una fila por cada accionista de cada empresa; por eso debes repetir la misma empresa tantas veces como accionistas tenga. El porcentaje total de cada empresa debe sumar 100%.
A4: Código | B4: Empresa | C4: Accionista | D4: Vínculo familiar | E4: Número de acciones/cuotas | F4: Porcentaje | G4: Año de ingreso | H4: Forma de adquisición | I4: Valor pagado/aportado | J4: Quién aportó los recursos | K4: Estado civil al adquirir | L4: Convivía en ese momento | M4: Existe documento de adquisición | N4: Registro en libro accionistas | O4: Restricción vigente | P4: Valor estimado actual | Q4: Observaciones
A5: =IF(B5="","","ACC-"&TEXT(ROW()-4,"000")) -> ACC-001 | B5: Soluciones Comerciales y Constructivas | C5: =+FamiliaTable[[#This Row],[Nombre completo]] -> Nassif Abuita Nassar | D5: Fundador(a) | E5: 6120 | F5: 0.34 | G5: 2013 | H5: Constitución | I5: =+AccionistasTable[[#This Row],[Número de acciones/cuotas]]*10000 -> 61200000 | J5: =+AccionistasTable[[#This Row],[Accionista]] -> Nassif Abuita Nassar | K5: Separado(a) | L5: Sí | M5: No | N5: No | O5: No aplica | P5: =+$S$9*AccionistasTable[[#This Row],[Porcentaje]] -> 2.189684e+08
A6: =IF(B6="","","ACC-"&TEXT(ROW()-4,"000")) -> ACC-002 | B6: Soluciones Comerciales y Constructivas | C6: =+FamiliaTable[[#This Row],[Nombre completo]] -> Gloria Maria Correa Rivera | D6: Fundador(a) | E6: 6480 | F6: 0.36 | G6: 2013 | H6: Constitución | I6: =+AccionistasTable[[#This Row],[Número de acciones/cuotas]]*10000 -> 64800000 | J6: =+AccionistasTable[[#This Row],[Accionista]] -> Gloria Maria Correa Rivera | K6: Separado(a) | L6: Sí | M6: No | N6: No | O6: No aplica | P6: =+$S$9*AccionistasTable[[#This Row],[Porcentaje]] -> 2.318489e+08
A7: =IF(B7="","","ACC-"&TEXT(ROW()-4,"000")) -> ACC-003 | B7: Soluciones Comerciales y Constructivas | C7: =+FamiliaTable[[#This Row],[Nombre completo]] -> Said Latif Abuita Correa | D7: Hijo(a) | E7: 2700 | F7: 0.15 | G7: 2013 | H7: Constitución | I7: =+AccionistasTable[[#This Row],[Número de acciones/cuotas]]*10000 -> 27000000 | J7: =+AccionistasTable[[#This Row],[Accionista]] -> Said Latif Abuita Correa | K7: Soltero(a) | L7: No | M7: No | N7: No | O7: No aplica | P7: =+$S$9*AccionistasTable[[#This Row],[Porcentaje]] -> 96603708
A8: =IF(B8="","","ACC-"&TEXT(ROW()-4,"000")) -> ACC-004 | B8: Soluciones Comerciales y Constructivas | C8: =+FamiliaTable[[#This Row],[Nombre completo]] -> Karam Nassif Abuita Correa | D8: Hijo(a) | E8: 2700 | F8: 0.15 | G8: 2013 | H8: Constitución | I8: =+AccionistasTable[[#This Row],[Número de acciones/cuotas]]*10000 -> 27000000 | J8: =+AccionistasTable[[#This Row],[Accionista]] -> Karam Nassif Abuita Correa | K8: Soltero(a) | L8: No | M8: No | N8: No | O8: No aplica | P8: =+$S$9*AccionistasTable[[#This Row],[Porcentaje]] -> 96603708
A9: =IF(B9="","","ACC-"&TEXT(ROW()-4,"000")) -> ACC-005 | B9: Diseños y Soluciones Creativas | C9: Gloria Maria Correa Rivera | D9: Fundador(a) | E9: 34020 | F9: 0.21 | G9: 2005 | H9: Constitución | I9: =+AccionistasTable[[#This Row],[Número de acciones/cuotas]]*1000 -> 34020000 | J9: =+AccionistasTable[[#This Row],[Accionista]] -> Gloria Maria Correa Rivera | K9: Separado(a) | L9: Sí | M9: No | N9: No | O9: No aplica | S9: =644024719.18 -> 6.4402472e+08
A10: =IF(B10="","","ACC-"&TEXT(ROW()-4,"000")) -> ACC-006 | B10: Diseños y Soluciones Creativas | C10: Nassif Abuita Nassar | D10: Fundador(a) | E10: 30780 | F10: 0.19 | G10: 2005 | H10: Cesión | I10: =+AccionistasTable[[#This Row],[Número de acciones/cuotas]]*1000 -> 30780000 | J10: Gloria Maria Correa Rivera | K10: Separado(a) | L10: Sí | M10: No | N10: No | O10: No aplica
A11: =IF(B11="","","ACC-"&TEXT(ROW()-4,"000")) -> ACC-007 | B11: Diseños y Soluciones Creativas | C11: Said Latif Abuita Correa | D11: Hijo(a) | E11: 8100 | F11: 0.05 | G11: 2016 | H11: Cesión | I11: =+AccionistasTable[[#This Row],[Número de acciones/cuotas]]*1000 -> 8100000 | J11: =+J9 -> Gloria Maria Correa Rivera | K11: Soltero(a) | L11: No | M11: No | N11: No | O11: No aplica
A12: =IF(B12="","","ACC-"&TEXT(ROW()-4,"000")) -> ACC-008 | B12: Diseños y Soluciones Creativas | C12: Karam Nassif Abuita Correa | D12: Hijo(a) | E12: 8100 | F12: 0.05 | G12: 2016 | H12: Cesión | I12: =+AccionistasTable[[#This Row],[Número de acciones/cuotas]]*1000 -> 8100000 | J12: Gloria Maria Correa Rivera | K12: Soltero(a) | L12: No | M12: No | N12: No | O12: No aplica
A13: =IF(B13="","","ACC-"&TEXT(ROW()-4,"000")) -> ACC-009 | B13: =+EmpresasTable[[#This Row],[Razón social]] -> 0 | C13: =+FamiliaTable[[#This Row],[Nombre completo]] -> 0 | I13: =+AccionistasTable[[#This Row],[Número de acciones/cuotas]]*10000 -> 0 | J13: =+AccionistasTable[[#This Row],[Accionista]] -> 0 | P13: =+$S$9*AccionistasTable[[#This Row],[Porcentaje]] -> 0
A14: =IF(B14="","","ACC-"&TEXT(ROW()-4,"000")) -> ACC-010 | B14: =+EmpresasTable[[#This Row],[Razón social]] -> 0 | C14: =+FamiliaTable[[#This Row],[Nombre completo]] -> 0 | I14: =+AccionistasTable[[#This Row],[Número de acciones/cuotas]]*10000 -> 0 | J14: =+AccionistasTable[[#This Row],[Accionista]] -> 0 | P14: =+$S$9*AccionistasTable[[#This Row],[Porcentaje]] -> 0
A15: =IF(B15="","","ACC-"&TEXT(ROW()-4,"000")) -> ACC-011 | B15: =+EmpresasTable[[#This Row],[Razón social]] -> 0 | C15: =+FamiliaTable[[#This Row],[Nombre completo]] -> 0 | I15: =+AccionistasTable[[#This Row],[Número de acciones/cuotas]]*10000 -> 0 | J15: =+AccionistasTable[[#This Row],[Accionista]] -> 0 | P15: =+$S$9*AccionistasTable[[#This Row],[Porcentaje]] -> 0
A16: =IF(B16="","","ACC-"&TEXT(ROW()-4,"000")) -> ACC-012 | B16: =+EmpresasTable[[#This Row],[Razón social]] -> 0 | C16: =+FamiliaTable[[#This Row],[Nombre completo]] -> 0 | I16: =+AccionistasTable[[#This Row],[Número de acciones/cuotas]]*10000 -> 0 | J16: =+AccionistasTable[[#This Row],[Accionista]] -> 0 | P16: =+$S$9*AccionistasTable[[#This Row],[Porcentaje]] -> 0
A17: =IF(B17="","","ACC-"&TEXT(ROW()-4,"000")) -> ACC-013 | B17: =+EmpresasTable[[#This Row],[Razón social]] -> 0 | C17: =+FamiliaTable[[#This Row],[Nombre completo]] -> 0 | I17: =+AccionistasTable[[#This Row],[Número de acciones/cuotas]]*10000 -> 0 | J17: =+AccionistasTable[[#This Row],[Accionista]] -> 0 | P17: =+$S$9*AccionistasTable[[#This Row],[Porcentaje]] -> 0
A18: =IF(B18="","","ACC-"&TEXT(ROW()-4,"000")) -> ACC-014 | B18: =+EmpresasTable[[#This Row],[Razón social]] -> 0 | C18: =+FamiliaTable[[#This Row],[Nombre completo]] -> 0 | I18: =+AccionistasTable[[#This Row],[Número de acciones/cuotas]]*10000 -> 0 | J18: =+AccionistasTable[[#This Row],[Accionista]] -> 0 | P18: =+$S$9*AccionistasTable[[#This Row],[Porcentaje]] -> 0
A19: =IF(B19="","","ACC-"&TEXT(ROW()-4,"000")) -> ACC-015 | B19: =+EmpresasTable[[#This Row],[Razón social]] -> 0 | C19: =+FamiliaTable[[#This Row],[Nombre completo]] -> 0 | I19: =+AccionistasTable[[#This Row],[Número de acciones/cuotas]]*10000 -> 0 | J19: =+AccionistasTable[[#This Row],[Accionista]] -> 0 | P19: =+$S$9*AccionistasTable[[#This Row],[Porcentaje]] -> 0
A20: =IF(B20="","","ACC-"&TEXT(ROW()-4,"000")) -> ACC-016 | B20: =+EmpresasTable[[#This Row],[Razón social]] -> 0 | C20: =+FamiliaTable[[#This Row],[Nombre completo]] -> 0 | I20: =+AccionistasTable[[#This Row],[Número de acciones/cuotas]]*10000 -> 0 | J20: =+AccionistasTable[[#This Row],[Accionista]] -> 0 | P20: =+$S$9*AccionistasTable[[#This Row],[Porcentaje]] -> 0
A21: =IF(B21="","","ACC-"&TEXT(ROW()-4,"000")) -> ACC-017 | B21: =+EmpresasTable[[#This Row],[Razón social]] -> 0 | C21: =+FamiliaTable[[#This Row],[Nombre completo]] -> 0 | I21: =+AccionistasTable[[#This Row],[Número de acciones/cuotas]]*10000 -> 0 | J21: =+AccionistasTable[[#This Row],[Accionista]] -> 0 | P21: =+$S$9*AccionistasTable[[#This Row],[Porcentaje]] -> 0
A22: =IF(B22="","","ACC-"&TEXT(ROW()-4,"000")) -> ACC-018 | B22: =+EmpresasTable[[#This Row],[Razón social]] -> 0 | C22: =+FamiliaTable[[#This Row],[Nombre completo]] -> 0 | I22: =+AccionistasTable[[#This Row],[Número de acciones/cuotas]]*10000 -> 0 | J22: =+AccionistasTable[[#This Row],[Accionista]] -> 0 | P22: =+$S$9*AccionistasTable[[#This Row],[Porcentaje]] -> 0
A23: =IF(B23="","","ACC-"&TEXT(ROW()-4,"000")) -> ACC-019 | B23: =+EmpresasTable[[#This Row],[Razón social]] -> 0 | C23: =+FamiliaTable[[#This Row],[Nombre completo]] -> 0 | I23: =+AccionistasTable[[#This Row],[Número de acciones/cuotas]]*10000 -> 0 | J23: =+AccionistasTable[[#This Row],[Accionista]] -> 0 | P23: =+$S$9*AccionistasTable[[#This Row],[Porcentaje]] -> 0
A24: =IF(B24="","","ACC-"&TEXT(ROW()-4,"000")) -> ACC-020 | B24: =+EmpresasTable[[#This Row],[Razón social]] -> 0 | C24: =+FamiliaTable[[#This Row],[Nombre completo]] -> 0 | I24: =+AccionistasTable[[#This Row],[Número de acciones/cuotas]]*10000 -> 0 | J24: =+AccionistasTable[[#This Row],[Accionista]] -> 0 | P24: =+$S$9*AccionistasTable[[#This Row],[Porcentaje]] -> 0
... A104: =IF(B104="","","ACC-"&TEXT(ROW()-4,"000")) -> #VALUE! | B104: =+EmpresasTable[[#This Row],[Razón social]] -> #VALUE! | C104: =+FamiliaTable[[#This Row],[Nombre completo]] -> #VALUE! | I104: =+AccionistasTable[[#This Row],[Número de acciones/cuotas]]*10000 -> 0 | J104: =+AccionistasTable[[#This Row],[Accionista]] -> #VALUE! | P104: =+$S$9*AccionistasTable[[#This Row],[Porcentaje]] -> 0

Sheet 04_Patrimonio
A1: 04. INVENTARIO MAESTRO DE ACTIVOS FAMILIARES Y EMPRESARIALES | BL1: Categoría auxiliar | BM1: Subcategoría auxiliar | BO1: Lista única de categorías
BL2: Bienes inmuebles | BM2: Apartamento | BO2: Bienes inmuebles
A3: OBJETIVO: consolidar todos los activos personales, familiares y empresariales. REGLA: una fila representa un activo. No registres claves, números bancarios completos ni información innecesariamente sensible. Los valores pueden ser preliminares y luego actualizarse con documentos o avalúos. | BL3: Bienes inmuebles | BM3: Casa | BO3: Acciones, cuotas y participaciones societarias
A4: IDENTIFICACIÓN DEL ACTIVO | F4: TITULARIDAD Y RELACIÓN FAMILIAR | O4: ADQUISICIÓN Y ORIGEN PATRIMONIAL | X4: IDENTIFICACIÓN ESPECÍFICA Y UBICACIÓN | AA4: VALORACIÓN, DEUDA Y RENTABILIDAD | AM4: CLASIFICACIÓN ESTRATÉGICA | AP4: ESTADO JURÍDICO Y LIMITACIONES | AU4: SEGUROS | AY4: DOCUMENTOS Y CONTROL | BD4: PLANEACIÓN SUCESORAL | BF4: RIESGO, SEGUIMIENTO Y OBSERVACIONES | BL4: Bienes inmuebles | BM4: Local comercial | BO4: Inversiones financieras y títulos valores
A5: Código del activo | B5: Categoría | C5: Subcategoría (depende de la categoría) | D5: Nombre corto | E5: Descripción completa | F5: Ámbito patrimonial | G5: Tipo de titular | H5: Titular legal | I5: Beneficiario económico | J5: Empresa relacionada | K5: Generación familiar | L5: % de propiedad | M5: Copropietarios | N5: % de otros propietarios | O5: Fecha de adquisición | P5: Forma de adquisición | Q5: Valor original | R5: Moneda | S5: Fuente de recursos | T5: Quién aportó realmente | U5: Estado civil al adquirir | V5: Convivía al adquirir | W5: Clasificación patrimonial | X5: Identificador principal | Y5: Identificador secundario | Z5: Ubicación general | AA5: Valor contable | AB5: Valor fiscal | AC5: Valor comercial estimado | AD5: Fecha última valoración | AE5: Método de valoración | AF5: Fuente / avaluador | AG5: Deuda o saldo pendiente | AH5: Valor neto estimado | AI5: Ingreso anual | AJ5: Gasto anual | AK5: Ingreso neto anual | AL5: Rentabilidad neta | AM5: Activo productivo | AN5: Activo estratégico | AO5: Nivel de liquidez | AP5: Estado físico | AQ5: Estado jurídico | AR5: Tiene gravamen | AS5: Tipo de gravamen | AT5: Acreedor o beneficiario | AU5: Tiene seguro | AV5: Compañía aseguradora | AW5: Valor asegurado | AX5: Vencimiento del seguro | AY5: Documento principal de propiedad | AZ5: Estado del soporte | BA5: Carpeta digital creada | BB5: Ubicación del archivo | BC5: Restricción para transferir | BD5: Destino sucesoral propuesto | BE5: Beneficiario sucesoral propuesto | BF5: Nivel de riesgo | BG5: Nivel de prioridad | BH5: Fecha última revisión | BI5: Responsable de actualización | BJ5: Observaciones | BL5: Bienes inmuebles | BM5: Oficina | BO5: Dinero en caja y cuentas bancarias
A6: =IF(D6="","","ACT-"&TEXT(ROW()-5,"0000")) | F6: Compartido | AH6: =IF(AC6="","",AC6-IF(AG6="",0,AG6)) | AK6: =IF(AND(AI6="",AJ6=""),"",IF(AI6="",0,AI6)-IF(AJ6="",0,AJ6)) | AL6: =IFERROR(AK6/AC6,"") | BL6: Bienes inmuebles | BM6: Consultorio | BO6: Cuentas por cobrar y cartera
A7: =IF(D7="","","ACT-"&TEXT(ROW()-5,"0000")) | AH7: =IF(AC7="","",AC7-IF(AG7="",0,AG7)) | AK7: =IF(AND(AI7="",AJ7=""),"",IF(AI7="",0,AI7)-IF(AJ7="",0,AJ7)) | AL7: =IFERROR(AK7/AC7,"") | BL7: Bienes inmuebles | BM7: Bodega | BO7: Inventarios y mercancías
A8: =IF(D8="","","ACT-"&TEXT(ROW()-5,"0000")) | AH8: =IF(AC8="","",AC8-IF(AG8="",0,AG8)) | AK8: =IF(AND(AI8="",AJ8=""),"",IF(AI8="",0,AI8)-IF(AJ8="",0,AJ8)) | AL8: =IFERROR(AK8/AC8,"") | BL8: Bienes inmuebles | BM8: Lote urbano | BO8: Vehículos y equipos de transporte
A9: =IF(D9="","","ACT-"&TEXT(ROW()-5,"0000")) | AH9: =IF(AC9="","",AC9-IF(AG9="",0,AG9)) | AK9: =IF(AND(AI9="",AJ9=""),"",IF(AI9="",0,AI9)-IF(AJ9="",0,AJ9)) | AL9: =IFERROR(AK9/AC9,"") | BL9: Bienes inmuebles | BM9: Lote rural | BO9: Maquinaria, equipos y herramientas
A10: =IF(D10="","","ACT-"&TEXT(ROW()-5,"0000")) | AH10: =IF(AC10="","",AC10-IF(AG10="",0,AG10)) | AK10: =IF(AND(AI10="",AJ10=""),"",IF(AI10="",0,AI10)-IF(AJ10="",0,AJ10)) | AL10: =IFERROR(AK10/AC10,"") | BL10: Bienes inmuebles | BM10: Finca | BO10: Muebles, enseres y equipos de oficina
A11: =IF(D11="","","ACT-"&TEXT(ROW()-5,"0000")) | AH11: =IF(AC11="","",AC11-IF(AG11="",0,AG11)) | AK11: =IF(AND(AI11="",AJ11=""),"",IF(AI11="",0,AI11)-IF(AJ11="",0,AJ11)) | AL11: =IFERROR(AK11/AC11,"") | BL11: Bienes inmuebles | BM11: Edificio | BO11: Equipos tecnológicos
A12: =IF(D12="","","ACT-"&TEXT(ROW()-5,"0000")) | AH12: =IF(AC12="","",AC12-IF(AG12="",0,AG12)) | AK12: =IF(AND(AI12="",AJ12=""),"",IF(AI12="",0,AI12)-IF(AJ12="",0,AJ12)) | AL12: =IFERROR(AK12/AC12,"") | BL12: Bienes inmuebles | BM12: Parqueadero | BO12: Marcas y propiedad intelectual
A13: =IF(D13="","","ACT-"&TEXT(ROW()-5,"0000")) | AH13: =IF(AC13="","",AC13-IF(AG13="",0,AG13)) | AK13: =IF(AND(AI13="",AJ13=""),"",IF(AI13="",0,AI13)-IF(AJ13="",0,AJ13)) | AL13: =IFERROR(AK13/AC13,"") | BL13: Bienes inmuebles | BM13: Depósito | BO13: Software, dominios y activos digitales
A14: =IF(D14="","","ACT-"&TEXT(ROW()-5,"0000")) | AH14: =IF(AC14="","",AC14-IF(AG14="",0,AG14)) | AK14: =IF(AND(AI14="",AJ14=""),"",IF(AI14="",0,AI14)-IF(AJ14="",0,AJ14)) | AL14: =IFERROR(AK14/AC14,"") | BL14: Bienes inmuebles | BM14: Hotel | BO14: Derechos fiduciarios y patrimonios autónomos
A15: =IF(D15="","","ACT-"&TEXT(ROW()-5,"0000")) | AH15: =IF(AC15="","",AC15-IF(AG15="",0,AG15)) | AK15: =IF(AND(AI15="",AJ15=""),"",IF(AI15="",0,AI15)-IF(AJ15="",0,AJ15)) | AL15: =IFERROR(AK15/AC15,"") | BL15: Bienes inmuebles | BM15: Inmueble industrial | BO15: Derechos contractuales y concesiones
A16: =IF(D16="","","ACT-"&TEXT(ROW()-5,"0000")) | AH16: =IF(AC16="","",AC16-IF(AG16="",0,AG16)) | AK16: =IF(AND(AI16="",AJ16=""),"",IF(AI16="",0,AI16)-IF(AJ16="",0,AJ16)) | AL16: =IFERROR(AK16/AC16,"") | BL16: Bienes inmuebles | BM16: Inmueble de uso especial | BO16: Proyectos y construcciones en curso
A17: =IF(D17="","","ACT-"&TEXT(ROW()-5,"0000")) | AH17: =IF(AC17="","",AC17-IF(AG17="",0,AG17)) | AK17: =IF(AND(AI17="",AJ17=""),"",IF(AI17="",0,AI17)-IF(AJ17="",0,AJ17)) | AL17: =IFERROR(AK17/AC17,"") | BL17: Bienes inmuebles | BM17: Derecho sobre inmueble | BO17: Mejoras en bienes ajenos
A18: =IF(D18="","","ACT-"&TEXT(ROW()-5,"0000")) | AH18: =IF(AC18="","",AC18-IF(AG18="",0,AG18)) | AK18: =IF(AND(AI18="",AJ18=""),"",IF(AI18="",0,AI18)-IF(AJ18="",0,AJ18)) | AL18: =IFERROR(AK18/AC18,"") | BL18: Bienes inmuebles | BM18: Otro inmueble | BO18: Activos por derecho de uso
... A28: =IF(D28="","","ACT-"&TEXT(ROW()-5,"0000")) | AH28: =IF(AC28="","",AC28-IF(AG28="",0,AG28)) | AK28: =IF(AND(AI28="",AJ28=""),"",IF(AI28="",0,AI28)-IF(AJ28="",0,AJ28)) | AL28: =IFERROR(AK28/AC28,"") | BL28: Acciones, cuotas y participaciones societarias | BM28: Participación indirecta mediante holding | BO28: Otros activos
A29: =IF(D29="","","ACT-"&TEXT(ROW()-5,"0000")) | AH29: =IF(AC29="","",AC29-IF(AG29="",0,AG29)) | AK29: =IF(AND(AI29="",AJ29=""),"",IF(AI29="",0,AI29)-IF(AJ29="",0,AJ29)) | AL29: =IFERROR(AK29/AC29,"") | BL29: Acciones, cuotas y participaciones societarias | BM29: Derechos económicos
A30: =IF(D30="","","ACT-"&TEXT(ROW()-5,"0000")) | AH30: =IF(AC30="","",AC30-IF(AG30="",0,AG30)) | AK30: =IF(AND(AI30="",AJ30=""),"",IF(AI30="",0,AI30)-IF(AJ30="",0,AJ30)) | AL30: =IFERROR(AK30/AC30,"") | BL30: Acciones, cuotas y participaciones societarias | BM30: Derechos políticos
A31: =IF(D31="","","ACT-"&TEXT(ROW()-5,"0000")) | AH31: =IF(AC31="","",AC31-IF(AG31="",0,AG31)) | AK31: =IF(AND(AI31="",AJ31=""),"",IF(AI31="",0,AI31)-IF(AJ31="",0,AJ31)) | AL31: =IFERROR(AK31/AC31,"") | BL31: Acciones, cuotas y participaciones societarias | BM31: Nuda propiedad de acciones
A32: =IF(D32="","","ACT-"&TEXT(ROW()-5,"0000")) | AH32: =IF(AC32="","",AC32-IF(AG32="",0,AG32)) | AK32: =IF(AND(AI32="",AJ32=""),"",IF(AI32="",0,AI32)-IF(AJ32="",0,AJ32)) | AL32: =IFERROR(AK32/AC32,"") | BL32: Acciones, cuotas y participaciones societarias | BM32: Usufructo de acciones
A33: =IF(D33="","","ACT-"&TEXT(ROW()-5,"0000")) | AH33: =IF(AC33="","",AC33-IF(AG33="",0,AG33)) | AK33: =IF(AND(AI33="",AJ33=""),"",IF(AI33="",0,AI33)-IF(AJ33="",0,AJ33)) | AL33: =IFERROR(AK33/AC33,"") | BL33: Acciones, cuotas y participaciones societarias | BM33: Otra participación societaria
A34: =IF(D34="","","ACT-"&TEXT(ROW()-5,"0000")) | AH34: =IF(AC34="","",AC34-IF(AG34="",0,AG34)) | AK34: =IF(AND(AI34="",AJ34=""),"",IF(AI34="",0,AI34)-IF(AJ34="",0,AJ34)) | AL34: =IFERROR(AK34/AC34,"") | BL34: Inversiones financieras y títulos valores | BM34: CDT
A35: =IF(D35="","","ACT-"&TEXT(ROW()-5,"0000")) | AH35: =IF(AC35="","",AC35-IF(AG35="",0,AG35)) | AK35: =IF(AND(AI35="",AJ35=""),"",IF(AI35="",0,AI35)-IF(AJ35="",0,AJ35)) | AL35: =IFERROR(AK35/AC35,"") | BL35: Inversiones financieras y títulos valores | BM35: Bono
A36: =IF(D36="","","ACT-"&TEXT(ROW()-5,"0000")) | AH36: =IF(AC36="","",AC36-IF(AG36="",0,AG36)) | AK36: =IF(AND(AI36="",AJ36=""),"",IF(AI36="",0,AI36)-IF(AJ36="",0,AJ36)) | AL36: =IFERROR(AK36/AC36,"") | BL36: Inversiones financieras y títulos valores | BM36: Acción cotizada en bolsa
A37: =IF(D37="","","ACT-"&TEXT(ROW()-5,"0000")) | AH37: =IF(AC37="","",AC37-IF(AG37="",0,AG37)) | AK37: =IF(AND(AI37="",AJ37=""),"",IF(AI37="",0,AI37)-IF(AJ37="",0,AJ37)) | AL37: =IFERROR(AK37/AC37,"") | BL37: Inversiones financieras y títulos valores | BM37: ETF
A38: =IF(D38="","","ACT-"&TEXT(ROW()-5,"0000")) | AH38: =IF(AC38="","",AC38-IF(AG38="",0,AG38)) | AK38: =IF(AND(AI38="",AJ38=""),"",IF(AI38="",0,AI38)-IF(AJ38="",0,AJ38)) | AL38: =IFERROR(AK38/AC38,"") | BL38: Inversiones financieras y títulos valores | BM38: Fondo de inversión colectiva
A39: =IF(D39="","","ACT-"&TEXT(ROW()-5,"0000")) | AH39: =IF(AC39="","",AC39-IF(AG39="",0,AG39)) | AK39: =IF(AND(AI39="",AJ39=""),"",IF(AI39="",0,AI39)-IF(AJ39="",0,AJ39)) | AL39: =IFERROR(AK39/AC39,"") | BL39: Inversiones financieras y títulos valores | BM39: Fondo voluntario de pensiones
A40: =IF(D40="","","ACT-"&TEXT(ROW()-5,"0000")) | AH40: =IF(AC40="","",AC40-IF(AG40="",0,AG40)) | AK40: =IF(AND(AI40="",AJ40=""),"",IF(AI40="",0,AI40)-IF(AJ40="",0,AJ40)) | AL40: =IFERROR(AK40/AC40,"") | BL40: Inversiones financieras y títulos valores | BM40: Encargo fiduciario de inversión
... A205: =IF(D205="","","ACT-"&TEXT(ROW()-5,"0000")) | AH205: =IF(AC205="","",AC205-IF(AG205="",0,AG205)) | AK205: =IF(AND(AI205="",AJ205=""),"",IF(AI205="",0,AI205)-IF(AJ205="",0,AJ205)) | AL205: =IFERROR(AK205/AC205,"") | BL205: Activos por derecho de uso | BM205: Vehículo arrendado
BL206: Activos por derecho de uso | BM206: Maquinaria en leasing
BL207: Activos por derecho de uso | BM207: Equipo tecnológico arrendado
A208: GUÍA RÁPIDA PARA CAMPOS ESPECIALES | BL208: Activos por derecho de uso | BM208: Licencia de uso
A209: Identificador principal | B209: Dato que individualiza el activo: matrícula inmobiliaria, placa, NIT de sociedad, número de título, contrato, marca o cuenta enmascarada. | BL209: Activos por derecho de uso | BM209: Otro derecho de uso
A210: Identificador secundario | B210: Dato adicional: referencia catastral, VIN, número de certificado, clase de marca, número de póliza u otro. | BL210: Obras de arte, joyas y colecciones | BM210: Pintura
A211: Valor comercial estimado | B211: Valor actual aproximado. Indica en “Método de valoración” si proviene de avalúo, balance, mercado o estimación. | BL211: Obras de arte, joyas y colecciones | BM211: Escultura
A212: Valor neto estimado | B212: Se calcula automáticamente: valor comercial menos deuda o saldo pendiente. | BL212: Obras de arte, joyas y colecciones | BM212: Fotografía artística
A213: Ingreso neto anual | B213: Se calcula automáticamente: ingresos anuales menos gastos anuales. | BL213: Obras de arte, joyas y colecciones | BM213: Antigüedad
...

Sheet 05_Documentos
A1: 05. INVENTARIO DE DOCUMENTOS JURÍDICOS Y PATRIMONIALES
A3: OBJETIVO: saber qué documentos existen, cuáles faltan y cuáles deben actualizarse. UNIDAD DE REGISTRO: una fila por cada documento relacionado con una persona o empresa.
A4: Código | B4: Persona/empresa relacionada | C4: Categoria | D4: Tipo de documento | E4: Existe | F4: Fecha | G4: Estado | H4: Notaría/Cámara/entidad | I4: Ubicación del archivo | J4: Requiere actualización | K4: Responsable de conseguirlo | L4: Fecha objetivo | M4: Prioridad | N4: Observaciones
A5: =IF(B5="","","DOC-"&TEXT(ROW()-4,"000")) | C5: 01. Constitución y existencia de las empresas | D5: =HLOOKUP(DocumentosTable[[#This Row],[Categoria]],Listas!$H$1:$Z$27,1,FALSE) -> 01. Constitución y existencia de las empresas
A6: =IF(B6="","","DOC-"&TEXT(ROW()-4,"000")) | D6: =HLOOKUP(DocumentosTable[[#This Row],[Categoria]],Listas!$H$1:$Z$27,1,FALSE) -> #N/A
A7: =IF(B7="","","DOC-"&TEXT(ROW()-4,"000")) | D7: =HLOOKUP(DocumentosTable[[#This Row],[Categoria]],Listas!$H$1:$Z$27,1,FALSE) -> #N/A
A8: =IF(B8="","","DOC-"&TEXT(ROW()-4,"000")) | D8: =HLOOKUP(DocumentosTable[[#This Row],[Categoria]],Listas!$H$1:$Z$27,1,FALSE) -> #N/A
A9: =IF(B9="","","DOC-"&TEXT(ROW()-4,"000")) | D9: =HLOOKUP(DocumentosTable[[#This Row],[Categoria]],Listas!$H$1:$Z$27,1,FALSE) -> #N/A
A10: =IF(B10="","","DOC-"&TEXT(ROW()-4,"000")) | D10: =HLOOKUP(DocumentosTable[[#This Row],[Categoria]],Listas!$H$1:$Z$27,1,FALSE) -> #N/A
A11: =IF(B11="","","DOC-"&TEXT(ROW()-4,"000")) | D11: =HLOOKUP(DocumentosTable[[#This Row],[Categoria]],Listas!$H$1:$Z$27,1,FALSE) -> #N/A
A12: =IF(B12="","","DOC-"&TEXT(ROW()-4,"000")) | D12: =HLOOKUP(DocumentosTable[[#This Row],[Categoria]],Listas!$H$1:$Z$27,1,FALSE) -> #N/A
A13: =IF(B13="","","DOC-"&TEXT(ROW()-4,"000")) | D13: =HLOOKUP(DocumentosTable[[#This Row],[Categoria]],Listas!$H$1:$Z$27,1,FALSE) -> #N/A
A14: =IF(B14="","","DOC-"&TEXT(ROW()-4,"000")) | D14: =HLOOKUP(DocumentosTable[[#This Row],[Categoria]],Listas!$H$1:$Z$27,1,FALSE) -> #N/A
A15: =IF(B15="","","DOC-"&TEXT(ROW()-4,"000")) | D15: =HLOOKUP(DocumentosTable[[#This Row],[Categoria]],Listas!$H$1:$Z$27,1,FALSE) -> #N/A
A16: =IF(B16="","","DOC-"&TEXT(ROW()-4,"000")) | D16: =HLOOKUP(DocumentosTable[[#This Row],[Categoria]],Listas!$H$1:$Z$27,1,FALSE) -> #N/A
A17: =IF(B17="","","DOC-"&TEXT(ROW()-4,"000")) | D17: =HLOOKUP(DocumentosTable[[#This Row],[Categoria]],Listas!$H$1:$Z$27,1,FALSE) -> #N/A
... A104: =IF(B104="","","DOC-"&TEXT(ROW()-4,"000")) | D104: =HLOOKUP(DocumentosTable[[#This Row],[Categoria]],Listas!$H$1:$Z$27,1,FALSE) -> #N/A

Sheet 06_Riesgos
A1: 06. MATRIZ DE RIESGOS FAMILIARES, SOCIETARIOS Y SUCESORALES
A3: OBJETIVO: anticipar eventos que puedan afectar la propiedad, el control, la continuidad o la armonía familiar. UNIDAD DE REGISTRO: una fila por cada riesgo o evento identificado.
A4: Código | B4: Persona/empresa afectada | C4: Evento o riesgo | D4: Descripción | E4: Probabilidad | F4: Impacto | G4: Nivel de riesgo | H4: Medida preventiva propuesta | I4: Documento que debe regularlo | J4: Responsable | K4: Fecha objetivo | L4: Estado | M4: Prioridad | N4: Observaciones
A5: =IF(B5="","","RIE-"&TEXT(ROW()-4,"000"))
A6: =IF(B6="","","RIE-"&TEXT(ROW()-4,"000"))
A7: =IF(B7="","","RIE-"&TEXT(ROW()-4,"000"))
A8: =IF(B8="","","RIE-"&TEXT(ROW()-4,"000"))
A9: =IF(B9="","","RIE-"&TEXT(ROW()-4,"000"))
A10: =IF(B10="","","RIE-"&TEXT(ROW()-4,"000"))
A11: =IF(B11="","","RIE-"&TEXT(ROW()-4,"000"))
A12: =IF(B12="","","RIE-"&TEXT(ROW()-4,"000"))
A13: =IF(B13="","","RIE-"&TEXT(ROW()-4,"000"))
A14: =IF(B14="","","RIE-"&TEXT(ROW()-4,"000"))
A15: =IF(B15="","","RIE-"&TEXT(ROW()-4,"000"))
A16: =IF(B16="","","RIE-"&TEXT(ROW()-4,"000"))
... A84: =IF(B84="","","RIE-"&TEXT(ROW()-4,"000"))

Sheet 07_Decisiones
A1: 07. DECISIONES BASE DEL PROTOCOLO Y MATRIZ DE IMPLEMENTACIÓN
A3: OBJETIVO: recoger la voluntad de la familia antes de redactar documentos jurídicos. UNIDAD DE REGISTRO: una fila por cada regla o decisión que la familia debe discutir y aprobar.
A4: Código | B4: Tema | C4: Pregunta o decisión familiar | D4: Posición propuesta | E4: Acuerdo familiar | F4: Protocolo familiar | G4: Estatutos | H4: Acuerdo accionistas | I4: Capitulaciones/liquidación | J4: Testamento/sucesión | K4: Manual o política | L4: Requiere valoración | M4: Responsable | N4: Fecha objetivo | O4: Estado | P4: Observaciones
A5: =IF(B5="","","DEC-"&TEXT(ROW()-4,"000")) -> DEC-001 | B5: Propiedad | C5: ¿Las parejas de los descendientes podrán ser accionistas? | E5: Por definir
A6: =IF(B6="","","DEC-"&TEXT(ROW()-4,"000")) -> DEC-002 | B6: Propiedad | C6: ¿Los nietos podrán recibir acciones directamente? | E6: Por definir
A7: =IF(B7="","","DEC-"&TEXT(ROW()-4,"000")) -> DEC-003 | B7: Trabajo familiar | C7: ¿Un familiar puede ser accionista sin trabajar en la empresa? | E7: Por definir
A8: =IF(B8="","","DEC-"&TEXT(ROW()-4,"000")) -> DEC-004 | B8: Trabajo familiar | C8: ¿Qué requisitos deberá cumplir un familiar para trabajar en la empresa? | E8: Por definir
A9: =IF(B9="","","DEC-"&TEXT(ROW()-4,"000")) -> DEC-005 | B9: Matrimonio/unión | C9: ¿Qué protección se exigirá antes de futuras donaciones o transferencias de acciones? | E9: Por definir
A10: =IF(B10="","","DEC-"&TEXT(ROW()-4,"000")) -> DEC-006 | B10: Divorcio/separación | C10: ¿Qué ocurrirá si unas acciones son adjudicadas a un cónyuge o compañero? | E10: Por definir
A11: =IF(B11="","","DEC-"&TEXT(ROW()-4,"000")) -> DEC-007 | B11: Fallecimiento | C11: ¿Los herederos recibirán acciones o un valor económico? | E11: Por definir
A12: =IF(B12="","","DEC-"&TEXT(ROW()-4,"000")) -> DEC-008 | B12: Valoración | C12: ¿Cómo se determinará el valor de las acciones cuando alguien se retire? | E12: Por definir
A13: =IF(B13="","","DEC-"&TEXT(ROW()-4,"000")) -> DEC-009 | B13: Gobierno | C13: ¿Quién podrá integrar la junta directiva y el Consejo de Familia? | E13: Por definir
A14: =IF(B14="","","DEC-"&TEXT(ROW()-4,"000")) -> DEC-010 | B14: Sucesión | C14: ¿Quién dirigirá las empresas cuando los fundadores se retiren? | E14: Por definir
A15: =IF(B15="","","DEC-"&TEXT(ROW()-4,"000")) -> DEC-011 | B15: Dividendos | C15: ¿Qué porcentaje de utilidades se reinvertirá y cuál podrá distribuirse? | E15: Por definir
A16: =IF(B16="","","DEC-"&TEXT(ROW()-4,"000")) -> DEC-012 | B16: Conflictos | C16: ¿Cuál será el procedimiento para resolver conflictos familiares? | E16: Por definir
A17: =IF(B17="","","DEC-"&TEXT(ROW()-4,"000"))
A18: =IF(B18="","","DEC-"&TEXT(ROW()-4,"000"))
A19: =IF(B19="","","DEC-"&TEXT(ROW()-4,"000"))
A20: =IF(B20="","","DEC-"&TEXT(ROW()-4,"000"))
A21: =IF(B21="","","DEC-"&TEXT(ROW()-4,"000"))
A22: =IF(B22="","","DEC-"&TEXT(ROW()-4,"000"))
A23: =IF(B23="","","DEC-"&TEXT(ROW()-4,"000"))
A24: =IF(B24="","","DEC-"&TEXT(ROW()-4,"000"))
A25: =IF(B25="","","DEC-"&TEXT(ROW()-4,"000"))
A26: =IF(B26="","","DEC-"&TEXT(ROW()-4,"000"))
A27: =IF(B27="","","DEC-"&TEXT(ROW()-4,"000"))
A28: =IF(B28="","","DEC-"&TEXT(ROW()-4,"000"))
... A84: =IF(B84="","","DEC-"&TEXT(ROW()-4,"000"))

Sheet 08_Resumen
A1: 08. RESUMEN DE AVANCE Y ALERTAS
A3: OBJETIVO: mostrar automáticamente el avance, los documentos pendientes y los riesgos prioritarios. Esta hoja es de consulta; no es necesario diligenciar sus indicadores manualmente.
A4: Indicador | B4: Total | C4: Pendientes/alertas | D4: Interpretación | F4: Próximos pasos sugeridos
A5: Familiares registrados | B5: =COUNTA('01_Familia'!B5:B54) -> 4 | C5: =COUNTIF('01_Familia'!F5:F54,"Por confirmar") -> 0 | D5: Revisar estados civiles por confirmar. | F5: Paso | G5: Actividad | H5: Tipo
A6: Empresas registradas | B6: =COUNTA('02_Empresas'!B5:B34) -> 2 | C6: =COUNTIF('02_Empresas'!N5:N34,"No")+COUNTIF('02_Empresas'!N5:N34,"No sabe") -> 2 | D6: Estatutos pendientes o sin verificar. | F6: 1 | G6: Completar familia y empresas | H6: Prioridad inmediata
A7: Participaciones registradas | B7: =COUNTA('03_Accionistas'!B5:B104) -> 100 | C7: =COUNTIF('03_Accionistas'!N5:N104,"No")+COUNTIF('03_Accionistas'!N5:N104,"No sabe") -> 8 | D7: Registros accionarios pendientes. | F7: 2 | G7: Verificar libros de accionistas y estatutos | H7: Documental
A8: Bienes relevantes | B8: =COUNTA('04_Patrimonio'!B5:B84) -> 1 | C8: =COUNTIF('04_Patrimonio'!P5:P84,"Crítico")+COUNTIF('04_Patrimonio'!P5:P84,"Alto") -> 0 | D8: Bienes con prioridad alta o crítica. | F8: 3 | G8: Revisar estado matrimonial/patrimonial de cada hijo | H8: Jurídico familiar
A9: Documentos inventariados | B9: =COUNTA('05_Documentos'!B5:B104) -> 0 | C9: =COUNTIF('05_Documentos'!E5:E104,"No")+COUNTIF('05_Documentos'!J5:J104,"Sí") -> 0 | D9: Documentos inexistentes o por actualizar. | F9: 4 | G9: Discutir las 12 decisiones base | H9: Reunión familiar
A10: Riesgos identificados | B10: =COUNTA('06_Riesgos'!B5:B84) -> 0 | C10: =COUNTIF('06_Riesgos'!G5:G84,"Crítico")+COUNTIF('06_Riesgos'!G5:G84,"Alto") -> 0 | D10: Riesgos que requieren intervención prioritaria. | F10: 5 | G10: Preparar Protocolo Familiar – Versión 1 | H10: Después del diagnóstico
A11: Decisiones del protocolo | B11: =COUNTA('07_Decisiones'!B5:B84) -> 12 | C11: =COUNTIF('07_Decisiones'!E5:E84,"Por definir")+COUNTIF('07_Decisiones'!O5:O84,"Pendiente") -> 12 | D11: Decisiones todavía no acordadas.
A14: Semáforo general
A15: Nivel | B15: Significado | C15: Acción
A16: Bajo | B16: Información suficiente o riesgo controlado | C16: Mantener y documentar
A17: Medio | B17: Información incompleta o medida pendiente | C17: Revisar
A18: Alto/Crítico | B18: Puede afectar control, propiedad o continuidad | C18: Atención prioritaria

Sheet 00_Academia_Campos
A1: ACADEMIA PARA DILIGENCIAR EL PROTOCOLO FAMILIAR | I1: EJEMPLO PRÁCTICO – HOJA 03_ACCIONISTAS
I2: Empresa | J2: Accionista | K2: Vínculo | L2: Acciones | M2: Porcentaje
A3: Utiliza esta guía mientras completas las hojas 01 a 07. Cada campo incluye qué debes escribir, un ejemplo y el motivo por el cual se solicita. No se busca tomar decisiones jurídicas definitivas todavía; el propósito es reunir información cierta y detectar asuntos que deban verificarse. | I3: Empresa A S.A.S. | J3: Fundador | K3: Fundador(a) | L3: 600 | M3: 0.6
I4: Empresa A S.A.S. | J4: Hijo 1 | K4: Hijo(a) | L4: 200 | M4: 0.2
I5: Empresa A S.A.S. | J5: Hijo 2 | K5: Hijo(a) | L5: 200 | M5: 0.2
I6: Empresa B S.A.S. | J6: Fundador | K6: Fundador(a) | L6: 500 | M6: 0.5
A7: Hoja | B7: Qué representa una fila | C7: Campo | D7: Qué debes colocar | E7: Ejemplo | F7: Objetivo de la pregunta | G7: Alerta o recomendación | I7: Empresa B S.A.S. | J7: Hijo 1 | K7: Hijo(a) | L7: 500 | M7: 0.5
A8: 01_Familia | B8: Una persona | C8: Código | D8: No debes escribirlo; se genera automáticamente. | E8: FAM-001 | F8: Identificar cada registro sin confundir personas. | G8: No borrar la fórmula.
A9: 01_Familia | B9: Una persona | C9: Nombre completo | D9: Nombre de la persona vinculada a la familia empresaria. | E9: Nassif Abuita | F9: Construir el mapa familiar. | G9: No necesitas registrar cédula. | I9: Observa que “Empresa A” se repite tres veces porque tiene tres accionistas. Sus porcentajes suman 100%. “Empresa B” se repite dos veces porque tiene dos accionistas.
A10: 01_Familia | B10: Una persona | C10: Tipo de vínculo | D10: Relación de la persona con la familia o las empresas. | E10: Fundador(a), Hijo(a), Cónyuge | F10: Diferenciar descendientes, familia política y terceros. | G10: Usa el desplegable.
A11: 01_Familia | B11: Una persona | C11: Generación | D11: Lugar de la persona dentro de la familia empresaria. | E11: Primera, Segunda, Tercera | F11: Organizar la sucesión generacional. | G11: Fundadores: primera; hijos: segunda; nietos: tercera.
A12: 01_Familia | B12: Una persona | C12: Edad | D12: Edad actual aproximada. | E12: 42 | F12: Planear sucesión, formación y participación. | G12: Puede actualizarse posteriormente.
A13: 01_Familia | B13: Una persona | C13: Estado civil | D13: Situación civil o de convivencia actual. | E13: Casado(a), Unión libre | F13: Detectar posibles efectos conyugales o patrimoniales. | G13: No supongas; usa “Por confirmar”.
A14: 01_Familia | B14: Una persona | C14: Año matrimonio/convivencia | D14: Año en que se casó o comenzó la convivencia permanente. | E14: 2021 | F14: Relacionar fechas familiares con la adquisición de acciones. | G14: Puede ser aproximado inicialmente.
A15: 01_Familia | B15: Una persona | C15: Tiene capitulaciones | D15: Indica si celebró capitulaciones antes del matrimonio o unión. | E15: Sí / No / No sabe | F15: Saber si existe una protección patrimonial previa. | G15: Después se solicitará copia del documento.
